samples/sample_1_10000.csv
A,1,B,289,998
A,2,B,121,849
A,3,B,37,892
M,1,B,289,998
A,4,B,216,1172
A,5,B,275,1084
A,6,B,352,1145
M,4,B,167,1252
A,7,S,57,1217
T,57,1217
M,4,B,110,1252
X,7,S,57,1217
A,8,B,321,1391
A,9,S,126,1559
X,9,S,126,1559
A,10,S,332,1611
X,10,S,332,1611
M,4,B,269,1252
X,1,B,289,998
A,11,S,165,1646
A,12,B,127,1044
X,11,S,165,1646
A,13,B,14,1122
A,14,S,265,1663
A,15,B,316,1038
M,8,B,321,1391
A,16,B,116,1006
X,12,B,127,1044
X,16,B,116,1006
A,17,B,120,1050
A,18,S,230,1129
T,230,1129
M,8,B,91,1391
X,18,S,230,1129
A,19,B,105,1028
A,20,B,166,1032
A,21,S,217,1174
T,91,1174
T,126,1174
X,8,B,91,1391
M,21,S,126,1174
M,4,B,143,1252
X,21,S,126,1174
X,14,S,265,1663
X,20,B,166,1032
X,17,B,120,1050
A,22,S,235,1015
T,143,1015
T,92,1015
X,4,B,143,1252
M,22,S,92,1015
M,6,B,260,1145
X,22,S,92,1015
A,23,S,55,1164
A,24,B,152,963
M,23,S,55,988
T,55,988
M,6,B,205,1145
X,23,S,55,988
A,25,S,291,1208
X,25,S,291,1208
A,26,S,142,1260
M,26,S,302,1260
A,27,S,266,1021
T,205,1021
T,14,1021
T,47,1021
X,6,B,205,1145
M,27,S,61,1021
X,13,B,14,1122
M,27,S,47,1021
M,5,B,228,1084
X,27,S,47,1021
A,28,S,315,996
T,228,996
T,87,996
X,5,B,228,1084
M,28,S,87,996
M,15,B,229,1038
X,28,S,87,996
A,29,B,232,873
A,30,B,306,850
A,31,S,2,983
T,2,983
M,15,B,227,1038
X,31,S,2,983
A,32,S,232,984
T,227,984
T,5,984
X,15,B,227,1038
M,32,S,5,984
M,19,B,100,1028
X,32,S,5,984
A,33,B,143,942
A,34,S,187,989
T,100,989
X,19,B,100,1028
M,34,S,87,989
X,2,B,121,849
A,35,S,29,999
X,24,B,152,963
A,36,S,186,945
X,30,B,306,850
A,37,S,20,984
A,38,S,8,836
T,8,836
M,33,B,135,942
X,38,S,8,836
M,33,B,99,942
X,37,S,20,984
A,39,B,337,989
T,186,945
T,87,989
M,39,B,151,989
X,36,S,186,945
M,39,B,64,989
X,34,S,87,989
M,39,B,64,989
A,40,S,225,909
T,64,909
T,99,909
X,39,B,64,989
M,40,S,161,909
X,33,B,99,942
M,40,S,62,909
M,29,B,323,716
A,41,B,301,949
T,62,909
M,41,B,239,949
X,40,S,62,909
A,42,B,55,818
M,41,B,18,949
A,43,B,247,753
A,44,B,6,890
X,3,B,37,892
A,45,B,82,769
X,41,B,18,949
A,46,B,233,979
M,35,S,29,878
T,29,878
M,46,B,204,979
X,35,S,29,878
A,47,B,332,996
A,48,B,261,793
X,42,B,55,818
A,49,S,183,982
T,183,982
M,47,B,149,996
X,49,S,183,982
M,26,S,59,1260
M,26,S,367,1260
A,50,B,27,817
A,51,B,30,922
M,45,B,82,769
M,47,B,256,830
A,52,S,250,996
M,46,B,295,852
A,53,B,6,897
A,54,B,303,874
A,55,B,223,975
M,52,S,250,900
T,223,900
T,27,900
X,55,B,223,975
M,52,S,27,900
M,51,B,3,922
X,52,S,27,900
A,56,B,220,769
A,57,S,148,994
M,26,S,367,1260
M,51,B,203,922
X,47,B,256,830
A,58,S,7,876
T,7,876
M,51,B,196,922
X,58,S,7,876
A,59,B,202,779
X,26,S,367,1260
A,60,B,142,980
A,61,S,338,877
T,142,877
T,196,877
X,60,B,142,980
M,61,S,196,877
X,51,B,196,922
M,61,S,0,877
X,57,S,148,994
A,62,B,139,913
A,63,S,51,834
T,51,834
M,62,B,88,913
X,63,S,51,834
A,64,S,126,949
X,64,S,126,949
M,50,B,346,817
M,44,B,218,1028
X,53,B,6,897
A,65,S,20,1074
X,50,B,346,817
X,65,S,20,1074
A,66,S,348,822
T,218,822
T,88,822
T,42,822
X,44,B,218,1028
M,66,S,130,822
X,62,B,88,913
M,66,S,42,822
M,54,B,261,874
X,66,S,42,822
A,67,S,102,830
T,102,830
M,54,B,159,874
X,67,S,102,830
A,68,B,64,910
A,69,B,167,937
A,70,B,280,856
A,71,S,30,1031
A,72,B,280,934
A,73,S,106,889
T,106,889
M,69,B,61,937
X,73,S,106,889
A,74,B,153,800
M,69,B,127,937
X,71,S,30,1031
A,75,B,169,1115
A,76,S,110,980
T,110,980
M,75,B,59,1115
X,76,S,110,980
A,77,B,88,1045
A,78,B,374,1285
A,79,S,208,1369
M,72,B,217,934
A,80,S,229,1104
T,229,1104
M,78,B,145,1285
X,80,S,229,1104
X,79,S,208,1369
A,81,B,8,1425
A,82,B,325,1405
M,74,B,152,800
A,83,B,394,1276
X,83,B,394,1276
M,45,B,82,1639
A,84,S,75,1684
X,84,S,75,1684
A,85,B,91,1622
A,86,S,125,1861
X,86,S,125,1861
A,87,B,88,1479
X,69,B,127,937
X,68,B,64,910
A,88,B,4,1788
M,72,B,341,934
X,75,B,59,1115
X,46,B,295,852
A,89,B,41,1658
A,90,S,191,1995
M,85,B,91,1147
A,91,S,301,1007
T,4,1007
T,41,1007
T,82,1007
T,88,1007
T,8,1007
T,78,1007
X,88,B,4,1788
M,91,S,297,1007
X,89,B,41,1658
M,91,S,256,1007
X,45,B,82,1639
M,91,S,174,1007
X,87,B,88,1479
M,91,S,86,1007
X,81,B,8,1425
M,91,S,78,1007
M,82,B,247,1405
X,91,S,78,1007
X,82,B,247,1405
A,92,S,9,1112
T,9,1112
M,78,B,136,1285
X,92,S,9,1112
M,54,B,159,1022
A,93,B,380,1055
M,90,S,191,1355
A,94,S,245,1029
T,136,1029
T,91,1029
T,18,1029
X,78,B,136,1285
M,94,S,109,1029
X,85,B,91,1147
M,94,S,18,1029
M,93,B,362,1055
X,94,S,18,1029
A,95,S,235,1023
T,235,1023
M,93,B,127,1055
X,95,S,235,1023
A,96,S,104,1016
T,104,1016
M,93,B,23,1055
X,96,S,104,1016
M,54,B,319,897
A,97,B,19,966
A,98,B,58,994
M,90,S,255,1000
T,23,1000
T,88,1000
X,93,B,23,1055
M,90,S,232,1000
X,77,B,88,1045
M,90,S,144,1000
M,90,S,55,927
T,55,927
M,98,B,3,994
X,90,S,55,927
A,99,B,11,1148
A,100,B,299,1183
A,101,B,147,1094
A,102,S,278,1327
A,103,S,337,1054
T,299,1054
T,11,1054
T,27,1054
X,100,B,299,1183
M,103,S,38,1054
X,99,B,11,1148
M,103,S,27,1054
M,101,B,120,1094
X,103,S,27,1054
A,104,S,396,1021
T,120,1021
X,101,B,120,1094
M,104,S,276,1021
A,105,B,91,778
M,102,S,278,885
T,3,885
T,19,885
T,256,885
X,98,B,3,994
M,102,S,275,885
X,97,B,19,966
M,102,S,256,885
M,72,B,85,934
X,102,S,256,885
A,106,S,290,866
T,85,866
T,205,866
X,72,B,85,934
M,106,S,205,866
M,54,B,114,897
X,106,S,205,866
A,107,B,12,832
M,104,S,300,885
T,114,885
X,54,B,114,897
M,104,S,186,885
A,108,S,88,880
A,109,S,13,805
T,13,805
M,70,B,267,856
X,109,S,13,805
A,110,S,149,859
A,111,B,107,795
A,112,B,145,765
X,108,S,88,880
X,110,S,149,859
A,113,B,137,896
T,137,885
X,113,B,137,896
M,104,S,49,885
A,114,S,328,851
T,267,851
X,70,B,267,856
M,114,S,61,851
A,115,S,58,718
T,12,718
T,46,718
X,107,B,12,832
M,115,S,46,718
M,74,B,106,800
X,115,S,46,718
A,116,B,273,584
X,114,S,61,851
A,117,B,384,600
A,118,S,299,826
A,119,B,235,733
A,120,S,322,717
T,106,717
T,107,717
T,109,717
X,74,B,106,800
M,120,S,216,717
X,111,B,107,795
M,120,S,109,717
M,48,B,152,793
X,120,S,109,717
A,121,B,398,896
T,299,826
T,49,885
M,121,B,99,896
X,118,S,299,826
M,121,B,50,896
X,104,S,49,885
X,119,B,235,733
A,122,B,288,761
A,123,S,244,719
T,50,719
T,152,719
T,42,719
X,121,B,50,896
M,123,S,194,719
X,48,B,152,793
M,123,S,42,719
M,59,B,160,779
X,123,S,42,719
A,124,B,113,623
A,125,S,357,905
A,126,S,59,919
X,29,B,323,716
X,126,S,59,919
A,127,S,345,997
A,128,S,364,790
A,129,B,256,637
X,105,B,91,778
A,130,S,340,715
T,160,715
T,180,715
X,59,B,160,779
M,130,S,180,715
M,56,B,40,769
X,130,S,180,715
M,127,S,397,757
T,40,757
T,145,757
T,212,757
X,56,B,40,769
M,127,S,357,757
X,112,B,145,765
M,127,S,212,757
M,122,B,76,761
X,127,S,212,757
M,125,S,50,922
M,128,S,92,790
A,131,S,287,763
A,132,S,58,657
T,58,657
M,122,B,18,761
X,132,S,58,657
A,133,B,344,837
T,287,763
T,57,790
M,133,B,57,837
X,131,S,287,763
X,133,B,57,837
M,128,S,35,790
A,134,S,107,894
A,135,S,117,828
M,116,B,207,651
A,136,S,65,804
M,136,S,355,804
A,137,S,369,788
A,138,B,163,572
M,116,B,207,651
A,139,S,382,799
A,140,B,281,695
X,138,B,163,572
A,141,B,23,681
M,122,B,208,715
X,116,B,207,651
A,142,S,327,692
T,247,692
T,80,692
X,43,B,247,753
M,142,S,80,692
M,122,B,128,715
X,142,S,80,692
A,143,S,122,968
A,144,S,13,850
A,145,B,28,548
A,146,S,391,746
A,147,B,167,831
T,167,746
X,147,B,167,831
M,146,S,224,746
A,148,B,254,565
A,149,S,132,777
X,128,S,35,790
A,150,B,235,751
T,224,746
M,150,B,11,751
X,146,S,224,746
A,151,B,56,745
M,151,B,394,644
X,151,B,394,644
M,135,S,102,828
A,152,S,126,697
T,11,697
T,115,697
X,150,B,11,751
M,152,S,115,697
M,122,B,13,715
X,152,S,115,697
X,134,S,107,894
A,153,S,53,753
M,148,B,254,781
T,53,753
T,132,777
M,148,B,201,781
X,153,S,53,753
M,148,B,69,781
X,149,S,132,777
X,144,S,13,850
A,154,S,232,816
A,155,B,3,834
T,3,788
X,155,B,3,834
M,137,S,366,788
X,140,B,281,695
A,156,S,260,874
A,157,S,100,859
M,129,B,256,742
M,137,S,366,788
A,158,B,310,766
M,141,B,23,673
M,156,S,260,874
A,159,S,66,914
M,158,B,310,645
A,160,B,74,558
X,156,S,260,874
A,161,S,68,693
T,68,693
M,148,B,1,781
X,161,S,68,693
M,139,S,208,885
A,162,B,334,716
A,163,B,41,875
T,41,788
X,163,B,41,875
M,137,S,325,788
A,164,B,51,573
M,159,S,66,914
M,135,S,102,815
M,154,S,232,816
A,165,B,85,868
T,85,788
X,165,B,85,868
M,137,S,240,788
A,166,S,385,916
A,167,B,119,876
T,119,788
X,167,B,119,876
M,137,S,121,788
X,154,S,232,816
A,168,B,313,875
T,121,788
T,192,804
M,168,B,192,875
