samples/sample_2_10000.csv
A,1,B,11,266
A,2,S,175,314
A,3,B,62,246
M,2,S,175,314
A,4,B,328,284
A,5,S,206,321
A,6,B,104,314
T,104,314
X,6,B,104,314
M,2,S,71,314
A,7,S,339,308
X,3,B,62,246
A,8,B,172,245
X,4,B,328,284
X,8,B,172,245
A,9,B,307,214
M,2,S,71,314
M,1,B,203,263
A,10,B,397,301
A,11,B,281,233
A,12,S,87,327
A,13,S,227,302
M,9,B,307,214
A,14,B,382,248
A,15,S,380,267
T,380,267
M,10,B,17,301
X,15,S,380,267
M,12,S,87,286
T,17,286
X,10,B,17,301
M,12,S,70,286
A,16,B,356,200
A,17,S,321,295
A,18,S,193,327
X,13,S,227,302
A,19,S,305,277
X,18,S,193,327
A,20,B,354,250
M,12,S,371,277
A,21,B,6,277
T,6,277
X,21,B,6,277
M,19,S,299,277
M,12,S,371,277
A,22,S,265,273
A,23,B,366,247
A,24,S,221,277
A,25,S,153,241
T,153,241
M,1,B,50,263
X,25,S,153,241
M,22,S,322,343
M,14,B,315,260
X,22,S,322,343
A,26,S,191,245
T,50,245
T,141,245
X,1,B,50,263
M,26,S,141,245
M,14,B,174,260
X,26,S,141,245
A,27,B,320,260
X,24,S,221,277
M,16,B,356,284
T,299,277
T,57,277
M,16,B,57,284
X,19,S,299,277
X,16,B,57,284
M,12,S,314,277
A,28,B,372,298
T,314,277
T,58,295
M,28,B,58,298
X,12,S,314,277
X,28,B,58,298
M,17,S,263,295
A,29,S,244,350
X,5,S,206,321
A,30,S,237,340
A,31,B,159,262
A,32,B,75,312
T,75,295
X,32,B,75,312
M,17,S,188,295
A,33,B,86,229
X,11,B,281,233
X,14,B,174,260
X,17,S,188,295
A,34,B,212,227
M,23,B,348,247
A,35,B,20,218
A,36,B,65,282
X,35,B,20,218
A,37,B,21,304
A,38,S,13,299
T,13,299
M,37,B,8,304
X,38,S,13,299
A,39,B,8,311
T,8,308
X,39,B,8,311
M,7,S,331,308
X,37,B,8,304
A,40,B,365,284
X,7,S,331,308
X,27,B,320,260
M,33,B,86,229
X,2,S,71,314
A,41,B,117,279
A,42,S,175,399
A,43,B,171,340
T,171,340
X,43,B,171,340
M,30,S,66,340
A,44,B,302,289
A,45,B,66,324
X,44,B,302,289
A,46,B,311,288
X,42,S,175,399
A,47,B,193,333
A,48,S,62,415
A,49,S,178,330
T,178,330
M,47,B,15,333
X,49,S,178,330
A,50,S,66,287
T,15,287
T,51,287
X,47,B,15,333
M,50,S,51,287
M,45,B,15,324
X,50,S,51,287
X,48,S,62,415
A,51,B,337,331
M,46,B,311,288
A,52,S,308,371
A,53,B,201,364
T,66,340
T,135,350
M,53,B,135,364
X,30,S,66,340
X,53,B,135,364
M,29,S,109,350
M,52,S,2,371
A,54,B,216,324
A,55,B,337,358
T,109,350
M,55,B,228,358
X,29,S,109,350
A,56,S,138,464
A,57,S,139,378
X,51,B,337,331
A,58,B,140,396
T,2,371
T,138,378
M,58,B,138,396
X,52,S,2,371
X,58,B,138,396
M,57,S,1,378
M,57,S,1,450
M,56,S,303,464
X,45,B,15,324
A,59,B,303,322
A,60,S,286,376
A,61,S,159,366
M,57,S,1,450
X,61,S,159,366
A,62,B,343,257
X,36,B,65,282
X,56,S,303,464
X,23,B,348,247
M,20,B,354,362
M,57,S,1,333
T,1,333
M,20,B,353,362
X,57,S,1,333
A,63,B,51,378
T,51,376
X,63,B,51,378
M,60,S,235,376
M,60,S,71,376
A,64,B,83,291
A,65,B,35,377
T,35,376
X,65,B,35,377
M,60,S,36,376
A,66,S,146,330
T,146,330
M,20,B,207,362
X,66,S,146,330
X,62,B,343,257
A,67,S,52,476
A,68,S,36,460
X,67,S,52,476
X,40,B,365,284
A,69,S,147,452
M,68,S,147,460
A,70,S,294,402
A,71,S,112,471
A,72,S,30,316
T,30,316
M,20,B,177,362
X,72,S,30,316
M,60,S,36,376
X,34,B,212,227
M,70,S,294,390
A,73,B,162,373
M,20,B,177,362
A,74,S,150,354
T,150,354
M,73,B,12,373
X,74,S,150,354
A,75,B,230,295
A,76,B,292,284
M,20,B,353,362
A,77,S,341,366
T,12,366
X,73,B,12,373
M,77,S,329,366
A,78,B,202,403
T,202,366
X,78,B,202,403
M,77,S,127,366
M,64,B,381,291
A,79,S,282,396
X,54,B,216,324
X,79,S,282,396
A,80,B,4,396
T,4,366
X,80,B,4,396
M,77,S,123,366
A,81,B,300,296
X,70,S,294,390
M,81,B,40,296
A,82,B,71,266
A,83,S,186,364
A,84,B,260,301
M,59,B,303,387
T,186,364
T,117,366
M,59,B,117,387
X,83,S,186,364
X,59,B,117,387
M,77,S,6,366
A,85,S,310,414
M,71,S,198,469
A,86,B,372,361
X,77,S,6,366
A,87,B,1,367
A,88,B,361,416
T,36,376
T,310,414
M,88,B,325,416
X,60,S,36,376
M,88,B,15,416
X,85,S,310,414
X,86,B,372,361
A,89,S,270,501
M,84,B,13,301
X,89,S,270,501
A,90,B,93,426
A,91,B,362,449
A,92,S,257,459
X,90,B,93,426
M,33,B,86,480
T,86,452
X,33,B,86,480
M,69,S,61,452
M,69,S,61,452
A,93,S,184,402
T,184,402
M,91,B,178,449
X,93,S,184,402
X,68,S,147,460
M,55,B,322,358
A,94,B,308,436
A,95,S,100,518
X,87,B,1,367
A,96,B,37,485
T,37,452
X,96,B,37,485
M,69,S,24,452
X,75,B,230,295
M,71,S,184,469
A,97,S,205,533
A,98,S,55,547
A,99,B,14,413
A,100,B,215,467
T,24,452
T,191,459
M,100,B,191,467
X,69,S,24,452
X,100,B,191,467
M,92,S,66,459
M,20,B,109,362
M,31,B,159,262
A,101,S,122,508
A,102,B,384,518
T,66,459
T,184,469
T,122,508
T,12,518
M,102,B,318,518
X,92,S,66,459
M,102,B,134,518
X,71,S,184,469
M,102,B,12,518
X,101,S,122,508
X,102,B,12,518
M,95,S,88,518
M,97,S,296,533
A,103,S,143,432
T,143,432
M,91,B,35,449
X,103,S,143,432
A,104,S,297,511
A,105,B,82,539
T,82,511
X,105,B,82,539
M,104,S,215,511
A,106,B,385,371
A,107,S,247,522
X,107,S,247,522
X,95,S,88,518
M,98,S,344,547
M,81,B,40,296
M,99,B,150,349
A,108,B,210,546
T,210,511
X,108,B,210,546
M,104,S,5,511
A,109,B,63,509
X,31,B,159,262
M,98,S,184,583
A,110,S,2,529
A,111,S,145,651
X,91,B,35,449
A,112,B,41,491
A,113,B,366,423
A,114,S,21,647
A,115,B,393,570
T,5,511
T,2,529
T,296,533
M,115,B,388,570
X,104,S,5,511
M,115,B,386,570
X,110,S,2,529
M,115,B,90,570
X,97,S,296,533
X,98,S,184,583
A,116,B,255,506
A,117,B,54,584
A,118,B,217,571
M,111,S,36,736
X,114,S,21,647
A,119,S,156,691
A,120,B,322,636
M,55,B,322,358
A,121,B,370,552
A,122,S,392,762
A,123,B,268,695
T,156,691
M,123,B,112,695
X,119,S,156,691
X,81,B,40,296
A,124,B,173,772
T,36,736
T,137,762
M,124,B,137,772
X,111,S,36,736
X,124,B,137,772
M,122,S,255,762
X,122,S,255,762
M,120,B,170,792
A,125,B,123,938
A,126,S,179,765
T,123,765
T,56,765
X,125,B,123,938
M,126,S,56,765
M,120,B,114,792
X,126,S,56,765
M,121,B,370,552
M,99,B,237,349
X,118,B,217,571
A,127,S,227,677
T,114,677
T,112,677
X,120,B,114,792
M,127,S,113,677
X,123,B,112,695
M,127,S,1,677
M,117,B,111,664
A,128,B,42,555
M,117,B,111,664
M,116,B,364,506
M,117,B,111,664
M,127,S,281,797
X,128,B,42,555
M,106,B,385,371
M,82,B,35,266
A,129,S,177,676
A,130,S,376,653
T,111,653
X,117,B,111,664
M,130,S,265,653
M,113,B,366,423
A,131,S,112,527
T,90,527
T,22,527
X,115,B,90,570
M,131,S,22,527
M,121,B,348,552
X,131,S,22,527
A,132,B,346,542
M,129,S,177,676
A,133,S,104,632
A,134,S,129,612
M,130,S,306,653
A,135,S,122,664
X,134,S,129,612
A,136,S,193,525
T,193,525
M,121,B,155,552
X,136,S,193,525
M,127,S,244,797
A,137,S,183,570
A,138,B,237,478
A,139,B,397,418
A,140,B,375,539
A,141,S,234,607
A,142,B,99,471
X,55,B,322,358
A,143,B,130,499
M,132,B,190,542
A,144,S,360,553
A,145,S,250,716
A,146,B,49,605
T,49,553
X,146,B,49,605
M,144,S,311,553
A,147,S,392,613
M,88,B,356,416
A,148,S,46,698
A,149,B,201,421
A,150,B,248,424
X,150,B,248,424
A,151,B,130,414
A,152,B,79,415
A,153,S,331,589
X,138,B,237,478
M,141,S,121,630
A,154,S,180,646
A,155,B,324,533
A,156,B,177,443
X,129,S,177,676
A,157,S,78,526
T,78,526
M,121,B,77,552
X,157,S,78,526
A,158,S,20,496
T,20,496
M,121,B,57,552
X,158,S,20,496
A,159,B,43,387
X,127,S,244,797
M,139,B,397,628
T,311,553
T,86,570
M,139,B,86,628
X,144,S,311,553
X,139,B,86,628
M,137,S,97,570
A,160,B,167,526
A,161,S,103,574
A,162,S,315,605
A,163,B,115,491
A,164,B,24,600
T,24,570
X,164,B,24,600
M,137,S,73,570
A,165,B,87,557
A,166,B,163,424
A,167,B,282,511
A,168,B,299,456
M,162,S,214,516
T,87,516
T,57,516
T,70,516
X,165,B,87,557
M,162,S,127,516
X,121,B,57,552
M,162,S,70,516
M,132,B,120,542
X,162,S,70,516
A,169,S,72,490
T,72,490
M,132,B,48,542
X,169,S,72,490
A,170,S,86,576
X,152,B,79,415
A,171,B,1,413
X,116,B,364,506
A,172,B,299,429
X,141,S,121,630
A,173,S,383,475
T,48,475
T,335,475
X,132,B,48,542
M,173,S,335,475
M,140,B,40,539
X,173,S,335,475
M,148,S,39,596
A,174,S,296,508
T,40,508
T,256,508
X,140,B,40,539
M,174,S,256,508
M,155,B,68,533
X,174,S,256,508
X,167,B,282,511
A,175,B,65,391
X,133,S,104,632
X,175,B,65,391
A,176,B,221,534
A,177,B,202,404
A,178,B,71,613
T,71,570
X,178,B,71,613
M,137,S,2,570
X,130,S,306,653
A,179,B,230,610
T,2,570
T,103,574
T,86,576
T,39,589
M,179,B,228,610
X,137,S,2,570
M,179,B,125,610
X,161,S,103,574
M,179,B,39,610
X,170,S,86,576
X,179,B,39,610
M,153,S,292,589
A,180,S,347,707
A,181,B,6,447
M,172,B,299,429
A,182,S,289,588
A,183,B,188,581
M,180,S,347,615
A,184,B,173,494
A,185,B,210,659
T,210,588
X,185,B,210,659
M,182,S,79,588
A,186,B,377,473
A,187,S,81,591
A,188,B,380,450
X,112,B,41,491
X,145,S,250,716
A,189,B,9,456
A,190,S,377,582
M,172,B,299,429
